Workbook

Sheet Apr'25  H2
B1: Fe 500
A2: Region / Date | B2: Ex-Ahmedabad | C2: Ex-Bangalore | D2: Ex-Chennai | E2: Ex-Delhi/NCR | F2: Ex-Durgapur | G2: Ex-Goa | H2: Ex-Hyderabad | I2: Ex-Jaipur | J2: Ex-Jalna | K2: Ex-Mandi Gobindgarh | L2: Ex-Mumbai | M2: Ex-Muzaffarnagar | N2: Ex-Patna | O2: Ex-Raigarh | P2: Ex-Raipur | Q2: Ex-Rourkela
A3: 45763 | E3: 48700 | I3: =_xlfn.XLOOKUP(A3,'steel Mint data'!A:A,'steel Mint data'!I:I) -> 47500 | K3: 48700 | P3: 45800 | Q3: 46000
A4: =A3+1 -> 45764 | E4: 48600 | I4: =_xlfn.XLOOKUP(A4,'steel Mint data'!A:A,'steel Mint data'!I:I) -> 47200 | K4: 48400 | P4: 45400 | Q4: 45800
A5: =A4+1 -> 45765 | E5: 48600 | I5: =_xlfn.XLOOKUP(A5,'steel Mint data'!A:A,'steel Mint data'!I:I) -> 47000 | K5: 48300 | P5: 45200 | Q5: 45700
A6: =A5+1 -> 45766 | E6: 48400 | I6: =_xlfn.XLOOKUP(A6,'steel Mint data'!A:A,'steel Mint data'!I:I) -> 46800 | K6: 48100 | P6: 44800 | Q6: 45600
A7: =A6+1 -> 45767 | I7: =_xlfn.XLOOKUP(A7,'steel Mint data'!A:A,'steel Mint data'!I:I) -> H
A8: =A7+1 -> 45768 | E8: 47900 | I8: =_xlfn.XLOOKUP(A8,'steel Mint data'!A:A,'steel Mint data'!I:I) -> 46800 | K8: 48000 | P8: 44700 | Q8: 45500
A9: =A8+1 -> 45769 | E9: 48600 | I9: =_xlfn.XLOOKUP(A9,'steel Mint data'!A:A,'steel Mint data'!I:I) -> 47500 | K9: 49000 | P9: 45600 | Q9: 46300
A10: =A9+1 -> 45770 | E10: 48600 | I10: =_xlfn.XLOOKUP(A10,'steel Mint data'!A:A,'steel Mint data'!I:I) -> 47300 | K10: 48900 | P10: 45200 | Q10: 45700
A11: =A10+1 -> 45771 | E11: =_xlfn.XLOOKUP(A11,'steel Mint data'!A:A,'steel Mint data'!D:D,"",0) -> 48400 | I11: =_xlfn.XLOOKUP(A11,'steel Mint data'!A:A,'steel Mint data'!I:I) -> 47300 | K11: =_xlfn.XLOOKUP(A11,'steel Mint data'!A:A,'steel Mint data'!L:L,"",0) -> 48900 | P11: =_xlfn.XLOOKUP(A11,'steel Mint data'!A:A,'steel Mint data'!Q:Q,"",0) -> 45200 | Q11: =_xlfn.XLOOKUP(A11,'steel Mint data'!A:A,'steel Mint data'!R:R,"",0) -> 45500
A12: =A11+1 -> 45772 | E12: =_xlfn.XLOOKUP(A12,'steel Mint data'!A:A,'steel Mint data'!D:D,"",0) -> 48300 | I12: =_xlfn.XLOOKUP(A12,'steel Mint data'!A:A,'steel Mint data'!I:I) -> 47000 | K12: =_xlfn.XLOOKUP(A12,'steel Mint data'!A:A,'steel Mint data'!L:L,"",0) -> 48700 | P12: =_xlfn.XLOOKUP(A12,'steel Mint data'!A:A,'steel Mint data'!Q:Q,"",0) -> 45000 | Q12: =_xlfn.XLOOKUP(A12,'steel Mint data'!A:A,'steel Mint data'!R:R,"",0) -> 45500
A13: =A12+1 -> 45773 | E13: =_xlfn.XLOOKUP(A13,'steel Mint data'!A:A,'steel Mint data'!D:D,"",0) -> 48100 | I13: =_xlfn.XLOOKUP(A13,'steel Mint data'!A:A,'steel Mint data'!I:I) -> 47000 | K13: =_xlfn.XLOOKUP(A13,'steel Mint data'!A:A,'steel Mint data'!L:L,"",0) -> 48500 | P13: =_xlfn.XLOOKUP(A13,'steel Mint data'!A:A,'steel Mint data'!Q:Q,"",0) -> 45000 | Q13: =_xlfn.XLOOKUP(A13,'steel Mint data'!A:A,'steel Mint data'!R:R,"",0) -> 45300
A14: =A13+1 -> 45774 | E14: =_xlfn.XLOOKUP(A14,'steel Mint data'!A:A,'steel Mint data'!D:D,"",0) -> H | I14: =_xlfn.XLOOKUP(A14,'steel Mint data'!A:A,'steel Mint data'!I:I) -> H | K14: =_xlfn.XLOOKUP(A14,'steel Mint data'!A:A,'steel Mint data'!L:L,"",0) -> H | P14: =_xlfn.XLOOKUP(A14,'steel Mint data'!A:A,'steel Mint data'!Q:Q,"",0) -> H | Q14: =_xlfn.XLOOKUP(A14,'steel Mint data'!A:A,'steel Mint data'!R:R,"",0) -> H
A15: =A14+1 -> 45775 | E15: =_xlfn.XLOOKUP(A15,'steel Mint data'!A:A,'steel Mint data'!D:D,"",0) -> 47800 | I15: =_xlfn.XLOOKUP(A15,'steel Mint data'!A:A,'steel Mint data'!I:I) -> 46500 | K15: =_xlfn.XLOOKUP(A15,'steel Mint data'!A:A,'steel Mint data'!L:L,"",0) -> 48300 | P15: =_xlfn.XLOOKUP(A15,'steel Mint data'!A:A,'steel Mint data'!Q:Q,"",0) -> 45000 | Q15: =_xlfn.XLOOKUP(A15,'steel Mint data'!A:A,'steel Mint data'!R:R,"",0) -> 44900
A16: =A15+1 -> 45776 | E16: =_xlfn.XLOOKUP(A16,'steel Mint data'!A:A,'steel Mint data'!D:D,"",0) -> 47800 | I16: =_xlfn.XLOOKUP(A16,'steel Mint data'!A:A,'steel Mint data'!I:I) -> 46500 | K16: =_xlfn.XLOOKUP(A16,'steel Mint data'!A:A,'steel Mint data'!L:L,"",0) -> 48200 | P16: =_xlfn.XLOOKUP(A16,'steel Mint data'!A:A,'steel Mint data'!Q:Q,"",0) -> 44800 | Q16: =_xlfn.XLOOKUP(A16,'steel Mint data'!A:A,'steel Mint data'!R:R,"",0) -> 44900
A17: =A16+1 -> 45777 | E17: =_xlfn.XLOOKUP(A17,'steel Mint data'!A:A,'steel Mint data'!D:D,"",0) -> 47300 | I17: =_xlfn.XLOOKUP(A17,'steel Mint data'!A:A,'steel Mint data'!I:I) -> 46200 | K17: =_xlfn.XLOOKUP(A17,'steel Mint data'!A:A,'steel Mint data'!L:L,"",0) -> 48200 | P17: =_xlfn.XLOOKUP(A17,'steel Mint data'!A:A,'steel Mint data'!Q:Q,"",0) -> 44500 | Q17: =_xlfn.XLOOKUP(A17,'steel Mint data'!A:A,'steel Mint data'!R:R,"",0) -> 44700
E19: =SUM(E3:E18) -> 627100 | K19: =SUM(K3:K18) -> 630200 | P19: =SUM(P3:P18) -> 586200 | Q19: =SUM(Q3:Q18) -> 591400
B20: Amba Shakti (NCR) | C20: API (Raipur) | D20: Aditya Industries (Mandi) | E20: Shree Ganesh (Rourkela) | F20: SKA Raipur | G20: Amba Gwalior | H20: SKA
A21: Avg Price - Divided by no of days steel mint price is available | B21: =E19/O21 -> 48238.462 | C21: =P19/O21 -> 45092.308 | D21: =K19/O21 -> 48476.923 | E21: =Q19/O21 -> 45492.308 | F21: =C21 -> 45092.308 | G21: =B21-800 -> 47438.462 | O21: =COUNT(P3:P18) -> 13
A22: BIS | B22: 1200 | C22: 2150 | D22: 400 | E22: 2200 | F22: 1800 | G22: 1200
A23: Loading Charges | B23: 200 | C23: 265 | D23: 250 | E23: 275 | F23: 275 | G23: 200
A24: Actual PO Price (base dia): A | B24: =SUM(B21:B23) -> 49638.462 | C24: =SUM(C21:C23) -> 47507.308 | D24: =SUM(D21:D23) -> 49126.923 | E24: =SUM(E21:E23) -> 47967.308 | F24: =SUM(F21:F23) -> 47167.308 | G24: =SUM(G21:G23) -> 48838.462 | H24: 47217 | K24: =52150-C24-1250 -> 3392.6923
A25: Notional PO: B | B25: 50900 | C25: 48415 | D25: 49550 | E25: 48575 | F25: 48575 | G25: 50300 | H25: 46875
A26: Change (A-B) | B26: =B24-B25 -> -1261.5385 | C26: =C24-C25 -> -907.69231 | D26: =D24-D25 -> -423.07692 | E26: =E24-E25 -> -607.69231 | F26: =F24-F25 -> -1407.6923 | G26: =G24-G25 -> -1461.5385
J27: =52500-C24-1250 -> 3742.6923
A28: Current PL | B28: 56400 | C28: 53650 | D28: 56900 | E28: 53650 | F28: 53650 | G28: =B28-800 -> 55600
A29: Current ex plant NR | B29: =B28-2300 -> 54100 | C29: =C28-2300 -> 51350 | D29: =D28-2300 -> 54600 | E29: =E28-2300 -> 51350 | F29: =F28-2300 -> 51350 | G29: =G28-2300 -> 53300
A30: Current GM: C | B30: =B29-B24 -> 4461.5385 | C30: =C29-C24 -> 3842.6923 | D30: =D29-D24 -> 5473.0769 | E30: =E29-E24 -> 3382.6923 | F30: =F29-F24 -> 4182.6923 | G30: =G29-G24 -> 4461.5385 | I30: =54500-G24-1000 -> 4661.5385
F31: as per H1
E32: Notional PO | F32: 46875

Sheet May'25 H1
B1: Fe 500
A2: Region / Date | B2: Ex-Ahmedabad | C2: Ex-Bangalore | D2: Ex-Chennai | E2: Ex-Delhi/NCR | F2: Ex-Durgapur | G2: Ex-Goa | H2: Ex-Hyderabad | I2: Ex-Jaipur | J2: Ex-Jalna | K2: Ex-Mandi Gobindgarh | L2: Ex-Mumbai | M2: Ex-Muzaffarnagar | N2: Ex-Patna | O2: Ex-Raigarh | P2: Ex-Raipur | Q2: Ex-Rourkela
A3: 45778 | E3: =_xlfn.XLOOKUP(A3,'steel Mint data'!A:A,'steel Mint data'!D:D,"",0) -> 47500 | I3: =_xlfn.XLOOKUP(A3,'steel Mint data'!A:A,'steel Mint data'!I:I,"",0) -> 46200 | K3: =_xlfn.XLOOKUP(A3,'steel Mint data'!A:A,'steel Mint data'!L:L,"",0) -> 48100 | P3: =_xlfn.XLOOKUP(A3,'steel Mint data'!A:A,'steel Mint data'!Q:Q,"",0) -> 44500 | Q3: =_xlfn.XLOOKUP(A3,'steel Mint data'!A:A,'steel Mint data'!R:R,"",0) -> 44600
A4: =A3+1 -> 45779 | E4: =_xlfn.XLOOKUP(A4,'steel Mint data'!A:A,'steel Mint data'!D:D,"",0) -> 47500 | I4: =_xlfn.XLOOKUP(A4,'steel Mint data'!A:A,'steel Mint data'!I:I,"",0) -> 46200 | K4: =_xlfn.XLOOKUP(A4,'steel Mint data'!A:A,'steel Mint data'!L:L,"",0) -> 48000 | P4: =_xlfn.XLOOKUP(A4,'steel Mint data'!A:A,'steel Mint data'!Q:Q,"",0) -> 44500 | Q4: =_xlfn.XLOOKUP(A4,'steel Mint data'!A:A,'steel Mint data'!R:R,"",0) -> 44300
A5: =A4+1 -> 45780 | E5: =_xlfn.XLOOKUP(A5,'steel Mint data'!A:A,'steel Mint data'!D:D,"",0) -> 47300 | I5: =_xlfn.XLOOKUP(A5,'steel Mint data'!A:A,'steel Mint data'!I:I,"",0) -> 46300 | K5: =_xlfn.XLOOKUP(A5,'steel Mint data'!A:A,'steel Mint data'!L:L,"",0) -> 48000 | P5: =_xlfn.XLOOKUP(A5,'steel Mint data'!A:A,'steel Mint data'!Q:Q,"",0) -> 44300 | Q5: =_xlfn.XLOOKUP(A5,'steel Mint data'!A:A,'steel Mint data'!R:R,"",0) -> 44500
A6: =A5+1 -> 45781 | E6: =_xlfn.XLOOKUP(A6,'steel Mint data'!A:A,'steel Mint data'!D:D,"",0) -> H | I6: =_xlfn.XLOOKUP(A6,'steel Mint data'!A:A,'steel Mint data'!I:I,"",0) -> H | K6: =_xlfn.XLOOKUP(A6,'steel Mint data'!A:A,'steel Mint data'!L:L,"",0) -> H | P6: =_xlfn.XLOOKUP(A6,'steel Mint data'!A:A,'steel Mint data'!Q:Q,"",0) -> H | Q6: =_xlfn.XLOOKUP(A6,'steel Mint data'!A:A,'steel Mint data'!R:R,"",0) -> H
A7: =A6+1 -> 45782 | E7: =_xlfn.XLOOKUP(A7,'steel Mint data'!A:A,'steel Mint data'!D:D,"",0) -> 47300 | I7: =_xlfn.XLOOKUP(A7,'steel Mint data'!A:A,'steel Mint data'!I:I,"",0) -> 46400 | K7: =_xlfn.XLOOKUP(A7,'steel Mint data'!A:A,'steel Mint data'!L:L,"",0) -> 48000 | P7: =_xlfn.XLOOKUP(A7,'steel Mint data'!A:A,'steel Mint data'!Q:Q,"",0) -> 44400 | Q7: =_xlfn.XLOOKUP(A7,'steel Mint data'!A:A,'steel Mint data'!R:R,"",0) -> 44500
A8: =A7+1 -> 45783 | E8: =_xlfn.XLOOKUP(A8,'steel Mint data'!A:A,'steel Mint data'!D:D,"",0) -> 47200 | I8: =_xlfn.XLOOKUP(A8,'steel Mint data'!A:A,'steel Mint data'!I:I,"",0) -> 46300 | K8: =_xlfn.XLOOKUP(A8,'steel Mint data'!A:A,'steel Mint data'!L:L,"",0) -> 48000 | P8: =_xlfn.XLOOKUP(A8,'steel Mint data'!A:A,'steel Mint data'!Q:Q,"",0) -> 44300 | Q8: =_xlfn.XLOOKUP(A8,'steel Mint data'!A:A,'steel Mint data'!R:R,"",0) -> 44300
A9: =A8+1 -> 45784 | E9: =_xlfn.XLOOKUP(A9,'steel Mint data'!A:A,'steel Mint data'!D:D,"",0) -> 47000 | I9: =_xlfn.XLOOKUP(A9,'steel Mint data'!A:A,'steel Mint data'!I:I,"",0) -> 46000 | K9: =_xlfn.XLOOKUP(A9,'steel Mint data'!A:A,'steel Mint data'!L:L,"",0) -> 47700 | P9: =_xlfn.XLOOKUP(A9,'steel Mint data'!A:A,'steel Mint data'!Q:Q,"",0) -> 44200 | Q9: =_xlfn.XLOOKUP(A9,'steel Mint data'!A:A,'steel Mint data'!R:R,"",0) -> 44200
A10: =A9+1 -> 45785 | E10: =_xlfn.XLOOKUP(A10,'steel Mint data'!A:A,'steel Mint data'!D:D,"",0) -> 47000 | I10: =_xlfn.XLOOKUP(A10,'steel Mint data'!A:A,'steel Mint data'!I:I,"",0) -> 46000 | K10: =_xlfn.XLOOKUP(A10,'steel Mint data'!A:A,'steel Mint data'!L:L,"",0) -> 47700 | P10: =_xlfn.XLOOKUP(A10,'steel Mint data'!A:A,'steel Mint data'!Q:Q,"",0) -> 44100 | Q10: =_xlfn.XLOOKUP(A10,'steel Mint data'!A:A,'steel Mint data'!R:R,"",0) -> 44000
A11: =A10+1 -> 45786 | E11: =_xlfn.XLOOKUP(A11,'steel Mint data'!A:A,'steel Mint data'!D:D,"",0) -> 47000 | I11: =_xlfn.XLOOKUP(A11,'steel Mint data'!A:A,'steel Mint data'!I:I,"",0) -> 46000 | K11: =_xlfn.XLOOKUP(A11,'steel Mint data'!A:A,'steel Mint data'!L:L,"",0) -> 47700 | P11: =_xlfn.XLOOKUP(A11,'steel Mint data'!A:A,'steel Mint data'!Q:Q,"",0) -> 43900 | Q11: =_xlfn.XLOOKUP(A11,'steel Mint data'!A:A,'steel Mint data'!R:R,"",0) -> 44000
A12: =A11+1 -> 45787 | E12: =_xlfn.XLOOKUP(A12,'steel Mint data'!A:A,'steel Mint data'!D:D,"",0) -> 47000 | I12: =_xlfn.XLOOKUP(A12,'steel Mint data'!A:A,'steel Mint data'!I:I,"",0) -> 45900 | K12: =_xlfn.XLOOKUP(A12,'steel Mint data'!A:A,'steel Mint data'!L:L,"",0) -> 47600 | P12: =_xlfn.XLOOKUP(A12,'steel Mint data'!A:A,'steel Mint data'!Q:Q,"",0) -> 43800 | Q12: =_xlfn.XLOOKUP(A12,'steel Mint data'!A:A,'steel Mint data'!R:R,"",0) -> 43800
A13: =A12+1 -> 45788 | E13: =_xlfn.XLOOKUP(A13,'steel Mint data'!A:A,'steel Mint data'!D:D,"",0) -> H | I13: =_xlfn.XLOOKUP(A13,'steel Mint data'!A:A,'steel Mint data'!I:I,"",0) -> H | K13: =_xlfn.XLOOKUP(A13,'steel Mint data'!A:A,'steel Mint data'!L:L,"",0) -> H | P13: =_xlfn.XLOOKUP(A13,'steel Mint data'!A:A,'steel Mint data'!Q:Q,"",0) -> H | Q13: =_xlfn.XLOOKUP(A13,'steel Mint data'!A:A,'steel Mint data'!R:R,"",0) -> H
A14: =A13+1 -> 45789 | E14: =_xlfn.XLOOKUP(A14,'steel Mint data'!A:A,'steel Mint data'!D:D,"",0) -> 47300 | I14: =_xlfn.XLOOKUP(A14,'steel Mint data'!A:A,'steel Mint data'!I:I,"",0) -> 46100 | K14: =_xlfn.XLOOKUP(A14,'steel Mint data'!A:A,'steel Mint data'!L:L,"",0) -> 47800 | P14: =_xlfn.XLOOKUP(A14,'steel Mint data'!A:A,'steel Mint data'!Q:Q,"",0) -> 44100 | Q14: =_xlfn.XLOOKUP(A14,'steel Mint data'!A:A,'steel Mint data'!R:R,"",0) -> 44100
A15: =A14+1 -> 45790 | E15: =_xlfn.XLOOKUP(A15,'steel Mint data'!A:A,'steel Mint data'!D:D,"",0) -> 47400 | I15: =_xlfn.XLOOKUP(A15,'steel Mint data'!A:A,'steel Mint data'!I:I,"",0) -> 45800 | K15: =_xlfn.XLOOKUP(A15,'steel Mint data'!A:A,'steel Mint data'!L:L,"",0) -> 47700 | P15: =_xlfn.XLOOKUP(A15,'steel Mint data'!A:A,'steel Mint data'!Q:Q,"",0) -> 43900 | Q15: =_xlfn.XLOOKUP(A15,'steel Mint data'!A:A,'steel Mint data'!R:R,"",0) -> 43800
... A17: =A16+1 -> 45792 | E17: =_xlfn.XLOOKUP(A17,'steel Mint data'!A:A,'steel Mint data'!D:D,"",0) -> 47200 | I17: =_xlfn.XLOOKUP(A17,'steel Mint data'!A:A,'steel Mint data'!I:I,"",0) -> 45600 | K17: =_xlfn.XLOOKUP(A17,'steel Mint data'!A:A,'steel Mint data'!L:L,"",0) -> 47500 | P17: =_xlfn.XLOOKUP(A17,'steel Mint data'!A:A,'steel Mint data'!Q:Q,"",0) -> 43500 | Q17: =_xlfn.XLOOKUP(A17,'steel Mint data'!A:A,'steel Mint data'!R:R,"",0) -> 43700
E19: =SUM(E3:E18) -> 614100 | K19: =SUM(K3:K18) -> 621300 | P19: =SUM(P3:P18) -> 573200 | Q19: =SUM(Q3:Q18) -> 573500
B20: Amba Shakti (NCR) | C20: API (Raipur) | D20: Aditya Industries (Mandi) | E20: Shree Ganesh (Rourkela) | F20: SKA Raipur | G20: Amba Gwalior
A21: Avg Price - Divided by no of days steel mint price is available | B21: =E19/O21 -> 47238.462 | C21: =P19/O21 -> 44092.308 | D21: =K19/O21 -> 47792.308 | E21: =Q19/O21 -> 44115.385 | F21: =C21 -> 44092.308 | G21: =B21-800 -> 46438.462 | O21: =COUNT(P3:P17) -> 13
A22: BIS | B22: 1200 | C22: 2150 | D22: 400 | E22: 2200 | F22: 1800 | G22: 1200 | I22: =55000-1500-1000-G24 -> 4661.5385 | L22: =54500-3500-C24 -> 4492.6923
A23: Loading Charges | B23: 200 | C23: 265 | D23: 250 | E23: 275 | F23: 275 | G23: 200 | J23: =C24-G24 -> -1331.1538 | K23: =53500-G24-1000 -> 4661.5385
A24: Actual PO Price (base dia): A | B24: =SUM(B21:B23) -> 48638.462 | C24: =SUM(C21:C23) -> 46507.308 | D24: =SUM(D21:D23) -> 48442.308 | E24: =SUM(E21:E23) -> 46590.385 | F24: =SUM(F21:F23) -> 46167.308 | G24: =SUM(G21:G23) -> 47838.462 | H24: =54500-2000-1000-G24 -> 3661.5385 | I24: 13 | K24: =53500-G25-1000 -> 4100 | M24: =52300-B24 -> 3661.5385 | O24: =G24+3500+1000 -> 52338.462 | P24: =52900-B24 -> 4261.5385
A25: Notional PO: B | B25: 49200 | C25: 47415 | D25: 48950 | E25: 47375 | F25: 47075 | G25: 48400 | H25: 32 | I25: 22 | J25: =I25/45 -> 0.48888889 | K25: =1500*J25 -> 733.33333 | M25: =52300-B25 -> 3100 | P25: =52900-B25 -> 3700
A26: Change (A-B) | B26: =B24-B25 -> -561.53846 | C26: =C24-C25 -> -907.69231 | D26: =D24-D25 -> -507.69231 | E26: =E24-E25 -> -784.61538 | F26: =F24-F25 -> -907.69231 | G26: =G24-G25 -> -561.53846
L27: =53500 -> 53500 | N27: 53750
A28: Current PL | B28: 56400 | C28: 53650 | D28: 56900 | E28: 53650 | F28: 53650 | G28: =B28-800 -> 55600 | L28: 1315 | N28: =53750-B24 -> 5111.5385
A29: Current ex plant NR | B29: =B28-2300 -> 54100 | C29: =C28-2300 -> 51350 | D29: =D28-2300 -> 54600 | E29: =E28-2300 -> 51350 | F29: =F28-2300 -> 51350 | G29: =G28-2300 -> 53300 | J29: =55500 -> 55500 | L29: 52500 | N29: =53750-B25 -> 4550
A30: Current GM: C | B30: =B29-B24 -> 5461.5385 | C30: =C29-C24 -> 4842.6923 | D30: =D29-D24 -> 6157.6923 | E30: =E29-E24 -> 4759.6154 | F30: =F29-F24 -> 5182.6923 | G30: =G29-G24 -> 5461.5385 | I30: =C24+1250+2500 -> 50257.308 | J30: 800 | L30: =L29-B24 -> 3861.5385
F31: as per H1 | L31: =L29-B25 -> 3300
B32: =54400-D24-1000 -> 4957.6923 | E32: Notional PO | F32: 46875 | J32: 52500 | P32: =53700-1050-D24 -> 4207.6923
J33: =J32-D24-1000 -> 3057.6923
D34: 51300 | H34: =53500-1250 -> 52250 | J34: =J32-D25-1000 -> 2550 | K34: =54500-2000-1000-G24 -> 3661.5385 | M34: =53000-1200 -> 51800
D35: =D34-C24-1250 -> 3542.6923 | F35: =51800-B24 -> 3161.5385 | H35: =52250-1000-G24 -> 3411.5385
A36: Kala Amb | B36: =D24+1000+3000 -> 52442.308 | D36: =51300-C25-1250 -> 2635 | F36: =51800-B25 -> 2600 | H36: =52250-1000-G25 -> 2850
A37: Gwalior | B37: =G24+1000+3000 -> 51838.462 | K37: =54000-1100-1000-G24 -> 4061.5385
G38: =5440 -> 5440
L39: =54400-D24-1000 -> 4957.6923
H40: 32mm | I40: 0.35 | J40: =I40*2000 -> 700
H41: =G24+1000 -> 48838.462

Sheet May'25 H2
B1: Fe 500
A2: Region / Date | B2: Ex-Ahmedabad | C2: Ex-Bangalore | D2: Ex-Chennai | E2: Ex-Delhi/NCR | F2: Ex-Durgapur | G2: Ex-Goa | H2: Ex-Hyderabad | I2: Ex-Jaipur | J2: Ex-Jalna | K2: Ex-Mandi Gobindgarh | L2: Ex-Mumbai | M2: Ex-Muzaffarnagar | N2: Ex-Patna | O2: Ex-Raigarh | P2: Ex-Raipur | Q2: Ex-Rourkela
A3: 45793 | E3: =_xlfn.XLOOKUP(A3,'steel Mint data'!A:A,'steel Mint data'!D:D,"",0) -> 47000 | I3: =_xlfn.XLOOKUP(A3,'steel Mint data'!A:A,'steel Mint data'!I:I,"",0) -> 45700 | K3: =_xlfn.XLOOKUP(A3,'steel Mint data'!A:A,'steel Mint data'!L:L,"",0) -> 47500 | P3: =_xlfn.XLOOKUP(A3,'steel Mint data'!A:A,'steel Mint data'!Q:Q,"",0) -> 43500 | Q3: =_xlfn.XLOOKUP(A3,'steel Mint data'!A:A,'steel Mint data'!R:R,"",0) -> 44000
A4: =A3+1 -> 45794 | E4: =_xlfn.XLOOKUP(A4,'steel Mint data'!A:A,'steel Mint data'!D:D,"",0) -> 46900 | I4: =_xlfn.XLOOKUP(A4,'steel Mint data'!A:A,'steel Mint data'!I:I,"",0) -> 45700 | K4: =_xlfn.XLOOKUP(A4,'steel Mint data'!A:A,'steel Mint data'!L:L,"",0) -> 47500 | P4: =_xlfn.XLOOKUP(A4,'steel Mint data'!A:A,'steel Mint data'!Q:Q,"",0) -> 43600 | Q4: =_xlfn.XLOOKUP(A4,'steel Mint data'!A:A,'steel Mint data'!R:R,"",0) -> 43800
A5: =A4+1 -> 45795 | E5: =_xlfn.XLOOKUP(A5,'steel Mint data'!A:A,'steel Mint data'!D:D,"",0) -> H | I5: =_xlfn.XLOOKUP(A5,'steel Mint data'!A:A,'steel Mint data'!I:I,"",0) -> H | K5: =_xlfn.XLOOKUP(A5,'steel Mint data'!A:A,'steel Mint data'!L:L,"",0) -> H | P5: =_xlfn.XLOOKUP(A5,'steel Mint data'!A:A,'steel Mint data'!Q:Q,"",0) -> H | Q5: =_xlfn.XLOOKUP(A5,'steel Mint data'!A:A,'steel Mint data'!R:R,"",0) -> H
A6: =A5+1 -> 45796 | E6: =_xlfn.XLOOKUP(A6,'steel Mint data'!A:A,'steel Mint data'!D:D,"",0) -> 46800 | I6: =_xlfn.XLOOKUP(A6,'steel Mint data'!A:A,'steel Mint data'!I:I,"",0) -> 45700 | K6: =_xlfn.XLOOKUP(A6,'steel Mint data'!A:A,'steel Mint data'!L:L,"",0) -> 47500 | P6: =_xlfn.XLOOKUP(A6,'steel Mint data'!A:A,'steel Mint data'!Q:Q,"",0) -> 43500 | Q6: =_xlfn.XLOOKUP(A6,'steel Mint data'!A:A,'steel Mint data'!R:R,"",0) -> 43700
A7: =A6+1 -> 45797 | E7: =_xlfn.XLOOKUP(A7,'steel Mint data'!A:A,'steel Mint data'!D:D,"",0) -> 46700 | I7: =_xlfn.XLOOKUP(A7,'steel Mint data'!A:A,'steel Mint data'!I:I,"",0) -> 45800 | K7: =_xlfn.XLOOKUP(A7,'steel Mint data'!A:A,'steel Mint data'!L:L,"",0) -> 47600 | P7: =_xlfn.XLOOKUP(A7,'steel Mint data'!A:A,'steel Mint data'!Q:Q,"",0) -> 43500 | Q7: =_xlfn.XLOOKUP(A7,'steel Mint data'!A:A,'steel Mint data'!R:R,"",0) -> 43900
A8: =A7+1 -> 45798 | E8: =_xlfn.XLOOKUP(A8,'steel Mint data'!A:A,'steel Mint data'!D:D,"",0) -> 46700 | I8: =_xlfn.XLOOKUP(A8,'steel Mint data'!A:A,'steel Mint data'!I:I,"",0) -> 45900 | K8: =_xlfn.XLOOKUP(A8,'steel Mint data'!A:A,'steel Mint data'!L:L,"",0) -> 47600 | P8: =_xlfn.XLOOKUP(A8,'steel Mint data'!A:A,'steel Mint data'!Q:Q,"",0) -> 43500 | Q8: =_xlfn.XLOOKUP(A8,'steel Mint data'!A:A,'steel Mint data'!R:R,"",0) -> 44100
A9: =A8+1 -> 45799 | E9: =_xlfn.XLOOKUP(A9,'steel Mint data'!A:A,'steel Mint data'!D:D,"",0) -> 46700 | I9: =_xlfn.XLOOKUP(A9,'steel Mint data'!A:A,'steel Mint data'!I:I,"",0) -> 45800 | K9: =_xlfn.XLOOKUP(A9,'steel Mint data'!A:A,'steel Mint data'!L:L,"",0) -> 47600 | P9: =_xlfn.XLOOKUP(A9,'steel Mint data'!A:A,'steel Mint data'!Q:Q,"",0) -> 43400 | Q9: =_xlfn.XLOOKUP(A9,'steel Mint data'!A:A,'steel Mint data'!R:R,"",0) -> 43900
A10: =A9+1 -> 45800 | E10: =_xlfn.XLOOKUP(A10,'steel Mint data'!A:A,'steel Mint data'!D:D,"",0) -> 46400 | I10: =_xlfn.XLOOKUP(A10,'steel Mint data'!A:A,'steel Mint data'!I:I,"",0) -> 45600 | K10: =_xlfn.XLOOKUP(A10,'steel Mint data'!A:A,'steel Mint data'!L:L,"",0) -> 47500 | P10: =_xlfn.XLOOKUP(A10,'steel Mint data'!A:A,'steel Mint data'!Q:Q,"",0) -> 43300 | Q10: =_xlfn.XLOOKUP(A10,'steel Mint data'!A:A,'steel Mint data'!R:R,"",0) -> 43300
A11: =A10+1 -> 45801 | E11: =_xlfn.XLOOKUP(A11,'steel Mint data'!A:A,'steel Mint data'!D:D,"",0) -> 46600 | I11: =_xlfn.XLOOKUP(A11,'steel Mint data'!A:A,'steel Mint data'!I:I,"",0) -> 45600 | K11: =_xlfn.XLOOKUP(A11,'steel Mint data'!A:A,'steel Mint data'!L:L,"",0) -> 47500 | P11: =_xlfn.XLOOKUP(A11,'steel Mint data'!A:A,'steel Mint data'!Q:Q,"",0) -> 43200 | Q11: =_xlfn.XLOOKUP(A11,'steel Mint data'!A:A,'steel Mint data'!R:R,"",0) -> 43100
A12: =A11+1 -> 45802 | E12: =_xlfn.XLOOKUP(A12,'steel Mint data'!A:A,'steel Mint data'!D:D,"",0) -> H | I12: =_xlfn.XLOOKUP(A12,'steel Mint data'!A:A,'steel Mint data'!I:I,"",0) -> H | K12: =_xlfn.XLOOKUP(A12,'steel Mint data'!A:A,'steel Mint data'!L:L,"",0) -> H | P12: =_xlfn.XLOOKUP(A12,'steel Mint data'!A:A,'steel Mint data'!Q:Q,"",0) -> H | Q12: =_xlfn.XLOOKUP(A12,'steel Mint data'!A:A,'steel Mint data'!R:R,"",0) -> H
A13: =A12+1 -> 45803 | E13: =_xlfn.XLOOKUP(A13,'steel Mint data'!A:A,'steel Mint data'!D:D,"",0) -> 46200 | I13: =_xlfn.XLOOKUP(A13,'steel Mint data'!A:A,'steel Mint data'!I:I,"",0) -> 45400 | K13: =_xlfn.XLOOKUP(A13,'steel Mint data'!A:A,'steel Mint data'!L:L,"",0) -> 47200 | P13: =_xlfn.XLOOKUP(A13,'steel Mint data'!A:A,'steel Mint data'!Q:Q,"",0) -> 43100 | Q13: =_xlfn.XLOOKUP(A13,'steel Mint data'!A:A,'steel Mint data'!R:R,"",0) -> 43100
A14: =A13+1 -> 45804 | E14: =_xlfn.XLOOKUP(A14,'steel Mint data'!A:A,'steel Mint data'!D:D,"",0) -> 46000 | I14: =_xlfn.XLOOKUP(A14,'steel Mint data'!A:A,'steel Mint data'!I:I,"",0) -> 45200 | K14: =_xlfn.XLOOKUP(A14,'steel Mint data'!A:A,'steel Mint data'!L:L,"",0) -> 47100 | P14: =_xlfn.XLOOKUP(A14,'steel Mint data'!A:A,'steel Mint data'!Q:Q,"",0) -> 42900 | Q14: =_xlfn.XLOOKUP(A14,'steel Mint data'!A:A,'steel Mint data'!R:R,"",0) -> 43000
A15: =A14+1 -> 45805 | E15: =_xlfn.XLOOKUP(A15,'steel Mint data'!A:A,'steel Mint data'!D:D,"",0) -> 45800 | I15: =_xlfn.XLOOKUP(A15,'steel Mint data'!A:A,'steel Mint data'!I:I,"",0) -> 45100 | K15: =_xlfn.XLOOKUP(A15,'steel Mint data'!A:A,'steel Mint data'!L:L,"",0) -> 47100 | P15: =_xlfn.XLOOKUP(A15,'steel Mint data'!A:A,'steel Mint data'!Q:Q,"",0) -> 42800 | Q15: =_xlfn.XLOOKUP(A15,'steel Mint data'!A:A,'steel Mint data'!R:R,"",0) -> 43000
... A18: =A17+1 -> 45808 | E18: =_xlfn.XLOOKUP(A18,'steel Mint data'!A:A,'steel Mint data'!D:D,"",0) -> 45800 | I18: =_xlfn.XLOOKUP(A18,'steel Mint data'!A:A,'steel Mint data'!I:I,"",0) -> 44900 | K18: =_xlfn.XLOOKUP(A18,'steel Mint data'!A:A,'steel Mint data'!L:L,"",0) -> 46800 | P18: =_xlfn.XLOOKUP(A18,'steel Mint data'!A:A,'steel Mint data'!Q:Q,"",0) -> 42400 | Q18: =_xlfn.XLOOKUP(A18,'steel Mint data'!A:A,'steel Mint data'!R:R,"",0) -> 42500
E19: =SUM(E3:E18) -> 649200 | I19: =SUM(I3:I18) -> 636200 | K19: =SUM(K3:K18) -> 662300 | P19: =SUM(P3:P18) -> 603600 | Q19: =SUM(Q3:Q18) -> 607400
B20: Amba Shakti (NCR) | C20: API (Raipur) | D20: Aditya Industries (Mandi) | E20: Shree Ganesh (Rourkela) | F20: SKA Raipur | G20: Amba Gwalior | H20: Rajasthan
A21: Avg Price - Divided by no of days steel mint price is available | B21: =E19/O21 -> 46371.429 | C21: =P19/O21 -> 43114.286 | D21: =K19/O21 -> 47307.143 | E21: =Q19/O21 -> 43385.714 | F21: =C21 -> 43114.286 | G21: =B21-800 -> 45571.429 | H21: =I19/O21 -> 45442.857 | J21: =I19/O21 -> 45442.857 | L21: =G24+1000+2700+4000 -> 54671.429 | O21: =COUNT(P3:P18) -> 14
A22: BIS | B22: 1200 | C22: 2150 | D22: 400 | E22: 2200 | F22: 1800 | G22: 1200 | H22: 800
A23: Loading Charges | B23: 200 | C23: 265 | D23: 250 | E23: 275 | F23: 275 | G23: 200 | H23: 270 | K23: =D24+800 -> 48757.143 | L23: =G24+1000 -> 47971.429
A24: Actual PO Price (base dia): A | B24: =SUM(B21:B23) -> 47771.429 | C24: =SUM(C21:C23) -> 45529.286 | D24: =SUM(D21:D23) -> 47957.143 | E24: =SUM(E21:E23) -> 45860.714 | F24: =SUM(F21:F23) -> 45189.286 | G24: =SUM(G21:G23) -> 46971.429 | H24: =SUM(H21:H23) -> 46512.857 | K24: =K23+1500 -> 50257.143
A25: Notional PO: B | B25: 48700 | C25: 46515 | D25: 48450 | F25: 46175 | G25: =B25-800 -> 47900 | H25: 47116 | I25: =H25-H23-H22 -> 46046 | K25: =53500-K24 -> 3242.8571 | M25: =48650-C25 -> 2135
A26: Change (A-B) | B26: =B24-B25 -> -928.57143 | C26: =C24-C25 -> -985.71429 | D26: =D24-D25 -> -492.85714 | E26: =E24-E25 -> 45860.714 | F26: =F24-F25 -> -985.71429 | G26: =G24-G25 -> -928.57143 | H26: =H24-H25 -> -603.14286 | O26: =52250-2600-C24 -> 4120.7143
K27: =53000-1300-1000 -> 50700 | M27: =52700-1500 -> 51200
A28: Current PL | B28: 55300 | C28: 52550 | D28: 55800 | E28: 53650 | F28: 52550 | G28: =B28-800 -> 54500 | H28: =B28-500 -> 54800 | K28: =K27-G24 -> 3728.5714 | M28: =M27-D25-800 -> 1950 | O28: =M27-D25-800 -> 1950
A29: Current ex plant NR | B29: =B28-2300 -> 53000 | C29: =C28-2300 -> 50250 | D29: =D28-2300 -> 53500 | E29: =E28-2300 -> 51350 | F29: =F28-2300 -> 50250 | G29: =G28-2300 -> 52200 | O29: =52700-D24-800-1500 -> 2442.8571 | P29: =O29-O28 -> 492.85714
A30: Current GM: C | B30: =B29-B24 -> 5228.5714 | C30: =C29-C24 -> 4720.7143 | D30: =D29-D24 -> 5542.8571 | E30: =E29-E24 -> 5489.2857 | F30: =F29-F24 -> 5060.7143 | G30: =G29-G24 -> 5228.5714
K31: =52250-2600-C24 -> 4120.7143
I35: =51700-1000-G24 -> 3728.5714
I36: =51700-1000-G25 -> 2800 | O36: =48900-C24 -> 3370.7143

Sheet Jun'25 H1
B1: Fe 500
A2: Region / Date | B2: Ex-Ahmedabad | C2: Ex-Bangalore | D2: Ex-Chennai | E2: Ex-Delhi/NCR | F2: Ex-Durgapur | G2: Ex-Goa | H2: Ex-Hyderabad | I2: Ex-Jaipur | J2: Ex-Jalna | K2: Ex-Mandi Gobindgarh | L2: Ex-Mumbai | M2: Ex-Muzaffarnagar | N2: Ex-Patna | O2: Ex-Raigarh | P2: Ex-Raipur | Q2: Ex-Rourkela
A3: 45809 | E3: =_xlfn.XLOOKUP(A3,'steel Mint data'!A:A,'steel Mint data'!D:D,"",0) -> H | I3: =_xlfn.XLOOKUP(A3,'steel Mint data'!A:A,'steel Mint data'!I:I,"",0) -> H | K3: =_xlfn.XLOOKUP(A3,'steel Mint data'!A:A,'steel Mint data'!L:L,"",0) -> H | P3: =_xlfn.XLOOKUP(A3,'steel Mint data'!A:A,'steel Mint data'!Q:Q,"",0) -> H | Q3: =_xlfn.XLOOKUP(A3,'steel Mint data'!A:A,'steel Mint data'!R:R,"",0) -> H
A4: =A3+1 -> 45810 | E4: =_xlfn.XLOOKUP(A4,'steel Mint data'!A:A,'steel Mint data'!D:D,"",0) -> 46000 | I4: =_xlfn.XLOOKUP(A4,'steel Mint data'!A:A,'steel Mint data'!I:I,"",0) -> 45300 | K4: =_xlfn.XLOOKUP(A4,'steel Mint data'!A:A,'steel Mint data'!L:L,"",0) -> 46800 | P4: =_xlfn.XLOOKUP(A4,'steel Mint data'!A:A,'steel Mint data'!Q:Q,"",0) -> 42500 | Q4: =_xlfn.XLOOKUP(A4,'steel Mint data'!A:A,'steel Mint data'!R:R,"",0) -> 42400
A5: =A4+1 -> 45811 | E5: =_xlfn.XLOOKUP(A5,'steel Mint data'!A:A,'steel Mint data'!D:D,"",0) -> 46000 | I5: =_xlfn.XLOOKUP(A5,'steel Mint data'!A:A,'steel Mint data'!I:I,"",0) -> 45100 | K5: =_xlfn.XLOOKUP(A5,'steel Mint data'!A:A,'steel Mint data'!L:L,"",0) -> 47100 | P5: =_xlfn.XLOOKUP(A5,'steel Mint data'!A:A,'steel Mint data'!Q:Q,"",0) -> 42200 | Q5: =_xlfn.XLOOKUP(A5,'steel Mint data'!A:A,'steel Mint data'!R:R,"",0) -> 42300
A6: =A5+1 -> 45812 | E6: =_xlfn.XLOOKUP(A6,'steel Mint data'!A:A,'steel Mint data'!D:D,"",0) -> 46100 | I6: =_xlfn.XLOOKUP(A6,'steel Mint data'!A:A,'steel Mint data'!I:I,"",0) -> 45100 | K6: =_xlfn.XLOOKUP(A6,'steel Mint data'!A:A,'steel Mint data'!L:L,"",0) -> 47100 | P6: =_xlfn.XLOOKUP(A6,'steel Mint data'!A:A,'steel Mint data'!Q:Q,"",0) -> 42000 | Q6: =_xlfn.XLOOKUP(A6,'steel Mint data'!A:A,'steel Mint data'!R:R,"",0) -> 42200
A7: =A6+1 -> 45813 | E7: =_xlfn.XLOOKUP(A7,'steel Mint data'!A:A,'steel Mint data'!D:D,"",0) -> 45800 | I7: =_xlfn.XLOOKUP(A7,'steel Mint data'!A:A,'steel Mint data'!I:I,"",0) -> 45000 | K7: =_xlfn.XLOOKUP(A7,'steel Mint data'!A:A,'steel Mint data'!L:L,"",0) -> 47200 | P7: =_xlfn.XLOOKUP(A7,'steel Mint data'!A:A,'steel Mint data'!Q:Q,"",0) -> 42000 | Q7: =_xlfn.XLOOKUP(A7,'steel Mint data'!A:A,'steel Mint data'!R:R,"",0) -> 42000
A8: =A7+1 -> 45814 | E8: =_xlfn.XLOOKUP(A8,'steel Mint data'!A:A,'steel Mint data'!D:D,"",0) -> 45800 | I8: =_xlfn.XLOOKUP(A8,'steel Mint data'!A:A,'steel Mint data'!I:I,"",0) -> 44800 | K8: =_xlfn.XLOOKUP(A8,'steel Mint data'!A:A,'steel Mint data'!L:L,"",0) -> 47100 | P8: =_xlfn.XLOOKUP(A8,'steel Mint data'!A:A,'steel Mint data'!Q:Q,"",0) -> 41900 | Q8: =_xlfn.XLOOKUP(A8,'steel Mint data'!A:A,'steel Mint data'!R:R,"",0) -> 41900
A9: =A8+1 -> 45815 | E9: =_xlfn.XLOOKUP(A9,'steel Mint data'!A:A,'steel Mint data'!D:D,"",0) -> 45700 | I9: =_xlfn.XLOOKUP(A9,'steel Mint data'!A:A,'steel Mint data'!I:I,"",0) -> 44600 | K9: =_xlfn.XLOOKUP(A9,'steel Mint data'!A:A,'steel Mint data'!L:L,"",0) -> 47000 | P9: =_xlfn.XLOOKUP(A9,'steel Mint data'!A:A,'steel Mint data'!Q:Q,"",0) -> 41700 | Q9: =_xlfn.XLOOKUP(A9,'steel Mint data'!A:A,'steel Mint data'!R:R,"",0) -> 41800
A10: =A9+1 -> 45816 | E10: =_xlfn.XLOOKUP(A10,'steel Mint data'!A:A,'steel Mint data'!D:D,"",0) -> H | I10: =_xlfn.XLOOKUP(A10,'steel Mint data'!A:A,'steel Mint data'!I:I,"",0) -> H | K10: =_xlfn.XLOOKUP(A10,'steel Mint data'!A:A,'steel Mint data'!L:L,"",0) -> H | P10: =_xlfn.XLOOKUP(A10,'steel Mint data'!A:A,'steel Mint data'!Q:Q,"",0) -> H | Q10: =_xlfn.XLOOKUP(A10,'steel Mint data'!A:A,'steel Mint data'!R:R,"",0) -> H
A11: =A10+1 -> 45817 | E11: =_xlfn.XLOOKUP(A11,'steel Mint data'!A:A,'steel Mint data'!D:D,"",0) -> 45500 | I11: =_xlfn.XLOOKUP(A11,'steel Mint data'!A:A,'steel Mint data'!I:I,"",0) -> 44600 | K11: =_xlfn.XLOOKUP(A11,'steel Mint data'!A:A,'steel Mint data'!L:L,"",0) -> 46900 | P11: =_xlfn.XLOOKUP(A11,'steel Mint data'!A:A,'steel Mint data'!Q:Q,"",0) -> 41500 | Q11: =_xlfn.XLOOKUP(A11,'steel Mint data'!A:A,'steel Mint data'!R:R,"",0) -> 41600
A12: =A11+1 -> 45818 | E12: =_xlfn.XLOOKUP(A12,'steel Mint data'!A:A,'steel Mint data'!D:D,"",0) -> 45600 | I12: =_xlfn.XLOOKUP(A12,'steel Mint data'!A:A,'steel Mint data'!I:I,"",0) -> 44600 | K12: =_xlfn.XLOOKUP(A12,'steel Mint data'!A:A,'steel Mint data'!L:L,"",0) -> 46900 | P12: =_xlfn.XLOOKUP(A12,'steel Mint data'!A:A,'steel Mint data'!Q:Q,"",0) -> 41400 | Q12: =_xlfn.XLOOKUP(A12,'steel Mint data'!A:A,'steel Mint data'!R:R,"",0) -> 41500
A13: =A12+1 -> 45819 | E13: =_xlfn.XLOOKUP(A13,'steel Mint data'!A:A,'steel Mint data'!D:D,"",0) -> 45600 | I13: =_xlfn.XLOOKUP(A13,'steel Mint data'!A:A,'steel Mint data'!I:I,"",0) -> 44400 | K13: =_xlfn.XLOOKUP(A13,'steel Mint data'!A:A,'steel Mint data'!L:L,"",0) -> 46900 | P13: =_xlfn.XLOOKUP(A13,'steel Mint data'!A:A,'steel Mint data'!Q:Q,"",0) -> 41400 | Q13: =_xlfn.XLOOKUP(A13,'steel Mint data'!A:A,'steel Mint data'!R:R,"",0) -> 41700
A14: =A13+1 -> 45820 | E14: =_xlfn.XLOOKUP(A14,'steel Mint data'!A:A,'steel Mint data'!D:D,"",0) -> 45500 | I14: =_xlfn.XLOOKUP(A14,'steel Mint data'!A:A,'steel Mint data'!I:I,"",0) -> 44300 | K14: =_xlfn.XLOOKUP(A14,'steel Mint data'!A:A,'steel Mint data'!L:L,"",0) -> 46800 | P14: =_xlfn.XLOOKUP(A14,'steel Mint data'!A:A,'steel Mint data'!Q:Q,"",0) -> 41400 | Q14: =_xlfn.XLOOKUP(A14,'steel Mint data'!A:A,'steel Mint data'!R:R,"",0) -> 41700
A15: =A14+1 -> 45821 | E15: =_xlfn.XLOOKUP(A15,'steel Mint data'!A:A,'steel Mint data'!D:D,"",0) -> 45400 | I15: =_xlfn.XLOOKUP(A15,'steel Mint data'!A:A,'steel Mint data'!I:I,"",0) -> 44300 | K15: =_xlfn.XLOOKUP(A15,'steel Mint data'!A:A,'steel Mint data'!L:L,"",0) -> 46600 | P15: =_xlfn.XLOOKUP(A15,'steel Mint data'!A:A,'steel Mint data'!Q:Q,"",0) -> 41300 | Q15: =_xlfn.XLOOKUP(A15,'steel Mint data'!A:A,'steel Mint data'!R:R,"",0) -> 41600
... A18: =A17+1 -> 45824 | E18: =_xlfn.XLOOKUP(A18,'steel Mint data'!A:A,'steel Mint data'!D:D,"",0) -> 45300 | I18: =_xlfn.XLOOKUP(A18,'steel Mint data'!A:A,'steel Mint data'!I:I,"",0) -> 44200 | K18: =_xlfn.XLOOKUP(A18,'steel Mint data'!A:A,'steel Mint data'!L:L,"",0) -> 46600 | P18: =_xlfn.XLOOKUP(A18,'steel Mint data'!A:A,'steel Mint data'!Q:Q,"",0) -> 41200 | Q18: =_xlfn.XLOOKUP(A18,'steel Mint data'!A:A,'steel Mint data'!R:R,"",0) -> 41500
E19: =SUM(E3:E18) -> 593600 | I19: =SUM(I3:I18) -> 580500 | K19: =SUM(K3:K18) -> 609600 | P19: =SUM(P3:P18) -> 541700 | Q19: =SUM(Q3:Q18) -> 543700
B20: Amba Shakti (NCR) | C20: API (Raipur) | D20: Aditya Industries (Mandi) | E20: Shree Ganesh (Rourkela) | F20: SKA Raipur | G20: Amba Gwalior | H20: Rajasthan
A21: Avg Price - Divided by no of days steel mint price is available | B21: =E19/O21 -> 45661.538 | C21: =P19/O21 -> 41669.231 | D21: =K19/O21 -> 46892.308 | E21: =Q19/O21 -> 41823.077 | F21: =C21 -> 41669.231 | G21: =B21-800 -> 44861.538 | H21: =I19/O21 -> 44653.846 | O21: =COUNT(P1:P18) -> 13
A22: BIS | B22: 1200 | C22: 2150 | D22: 400 | E22: 2200 | F22: 1800 | G22: 1200 | H22: 800 | Q22: =50300-800-47650 -> 1850
A23: Loading Charges | B23: 200 | C23: 265 | D23: 250 | E23: 275 | F23: 275 | G23: 200 | H23: 270 | J23: =C24+1250+3000 -> 48334.231 | K23: =50500-G24-1000-1000 -> 2238.4615
A24: Actual PO Price (base dia): A | B24: =SUM(B21:B23) -> 47061.538 | C24: =SUM(C21:C23) -> 44084.231 | D24: =SUM(D21:D23) -> 47542.308 | E24: =SUM(E21:E23) -> 44298.077 | F24: =SUM(F21:F23) -> 43744.231 | G24: =SUM(G21:G23) -> 46261.538 | H24: =SUM(H21:H23) -> 45723.846 | J24: =D24-B24 -> 480.76923 | K24: =J24-150 -> 330.76923 | M24: =50500-G24-1000-1000 -> 2238.4615 | O24: =52700-3700 -> 49000 | P24: =O24-1000-1000-G24 -> 738.46154
A25: Notional PO: B | B25: 47200 | C25: 44915 | D25: 47550 | F25: 44575 | G25: 46400 | H25: 45970 | J25: =55500-51800 -> 3700
A26: Change (A-B) | B26: =B24-B25 -> -138.46154 | C26: =C24-C25 -> -830.76923 | D26: =D24-D25 -> -7.6923077 | E26: =E24-E25 -> 44298.077 | F26: =F24-F25 -> -830.76923 | G26: =G24-G25 -> -138.46154 | H26: =H24-H25 -> -246.15385 | N26: =52700-4000 -> 48700
L27: =50600-B24 -> 3538.4615 | S27: =52100*45 -> 2344500
A28: Current PL | B28: 51300 | C28: 48550 | D28: 51800 | E28: 49650 | F28: 48550 | G28: 50500 | H28: 50800 | K28: =49600-2900-400-C24 -> 2215.7692 | L28: =50600-B25 -> 3400 | O28: =52700-4000 -> 48700 | P28: =50300-D24 -> 2757.6923
A29: Current ex plant NR | B29: =B28-500-(200+300+300)-250-400 -> 49350 | C29: =C28-500-(200+300+300)-250-400 -> 46600 | D29: =D28-500-(200+300+300)-250-400 -> 49850 | E29: =E28-500-(200+300+300)-250-400 -> 47700 | F29: =F28-500-(200+300+300)-250-400 -> 46600 | G29: =G28-500-(200+300+300)-250-400 -> 48550 | H29: =H28-500-(200+300+300)-250-400 -> 48850 | K29: =49600-2900-400-C25 -> 1385 | P29: =50300-D25 -> 2750
A30: Current GM: C | B30: =B29-B24 -> 2288.4615 | C30: =C29-C24 -> 2515.7692 | D30: =D29-D24 -> 2307.6923 | E30: =E29-E24 -> 3401.9231 | F30: =F29-F24 -> 2855.7692 | G30: =G29-G24 -> 2288.4615 | H30: =H29-H24 -> 3126.1538 | K30: =K28-K29 -> 830.76923 | M30: =50500-2200-300-1250-C24 -> 2665.7692
M31: =50500-2200-300-1250-C25 -> 1835 | N31: =M30-M31 -> 830.76923 | R31: =50600-550-D24 -> 2507.6923
B32: =B28-B24-2000 -> 2238.4615 | C32: =C28-C24-2000 -> 2465.7692 | D32: =D28-D24-2000 -> 2257.6923 | E32: =E28-E24-2000 -> 3351.9231 | F32: =F28-F24-2000 -> 2805.7692 | G32: =G28-G24-2000 -> 2238.4615 | H32: =H28-H24-2000 -> 3076.1538 | K32: =52100-2600-1250-C24 -> 4165.7692 | R32: =50600-550-D25 -> 2500
C33: =C24+3500+1250 -> 48834.231 | K33: =52100-2600-1250-C25 -> 3335 | L33: =51200-1200-B24 -> 2938.4615
C34: =50000-C33 -> 1165.7692 | J34: =50600-1200-B24 -> 2338.4615 | K34: =K32-K33 -> 830.76923 | L34: =51200-1000-D24 -> 2657.6923 | P34: =52100-2600-1250-C24 -> 4165.7692
A35: Plant | B35: Jun H1 notional | C35: =50000-C24-1250-3400 -> 1265.7692 | E35: =50000-D24-1000 -> 1457.6923 | J35: =50600-550-D24 -> 2507.6923 | P35: =52100-2600-1250-C25 -> 3335
A36: Sikandarabad | B36: 47200
A37: API, Raipur | B37: 44915
A38: SKA, Raipur | B38: 44575
A39: Kala Amb | B39: 47550
A40: Gwalior | B40: =B36-800 -> 46400 | D40: =53000-1800-B40-1000 -> 3800
A41: Jaipur | B41: 45970

Sheet Jun'25 H2
B1: Fe 500
A2: Region / Date | B2: Ex-Ahmedabad | C2: Ex-Bangalore | D2: Ex-Chennai | E2: Ex-Delhi/NCR | F2: Ex-Durgapur | G2: Ex-Goa | H2: Ex-Hyderabad | I2: Ex-Jaipur | J2: Ex-Jalna | K2: Ex-Mandi Gobindgarh | L2: Ex-Mumbai | M2: Ex-Muzaffarnagar | N2: Ex-Patna | O2: Ex-Raigarh | P2: Ex-Raipur | Q2: Ex-Rourkela
A3: 45824 | E3: =_xlfn.XLOOKUP(A3,'steel Mint data'!A:A,'steel Mint data'!D:D,"",0) -> 45300 | I3: =_xlfn.XLOOKUP(A3,'steel Mint data'!A:A,'steel Mint data'!I:I,"",0) -> 44200 | K3: =_xlfn.XLOOKUP(A3,'steel Mint data'!A:A,'steel Mint data'!L:L,"",0) -> 46600 | P3: =_xlfn.XLOOKUP(A3,'steel Mint data'!A:A,'steel Mint data'!Q:Q,"",0) -> 41200 | Q3: =_xlfn.XLOOKUP(A3,'steel Mint data'!A:A,'steel Mint data'!R:R,"",0) -> 41500
A4: =A3+1 -> 45825 | E4: =_xlfn.XLOOKUP(A4,'steel Mint data'!A:A,'steel Mint data'!D:D,"",0) -> 45400 | I4: =_xlfn.XLOOKUP(A4,'steel Mint data'!A:A,'steel Mint data'!I:I,"",0) -> 44200 | K4: =_xlfn.XLOOKUP(A4,'steel Mint data'!A:A,'steel Mint data'!L:L,"",0) -> 46600 | P4: =_xlfn.XLOOKUP(A4,'steel Mint data'!A:A,'steel Mint data'!Q:Q,"",0) -> 41200 | Q4: =_xlfn.XLOOKUP(A4,'steel Mint data'!A:A,'steel Mint data'!R:R,"",0) -> 41500
A5: =A4+1 -> 45826 | E5: =_xlfn.XLOOKUP(A5,'steel Mint data'!A:A,'steel Mint data'!D:D,"",0) -> 45400 | I5: =_xlfn.XLOOKUP(A5,'steel Mint data'!A:A,'steel Mint data'!I:I,"",0) -> 44200 | K5: =_xlfn.XLOOKUP(A5,'steel Mint data'!A:A,'steel Mint data'!L:L,"",0) -> 46600 | P5: =_xlfn.XLOOKUP(A5,'steel Mint data'!A:A,'steel Mint data'!Q:Q,"",0) -> 41000 | Q5: =_xlfn.XLOOKUP(A5,'steel Mint data'!A:A,'steel Mint data'!R:R,"",0) -> 41300
A6: =A5+1 -> 45827 | E6: =_xlfn.XLOOKUP(A6,'steel Mint data'!A:A,'steel Mint data'!D:D,"",0) -> 45300 | I6: =_xlfn.XLOOKUP(A6,'steel Mint data'!A:A,'steel Mint data'!I:I,"",0) -> 44000 | K6: =_xlfn.XLOOKUP(A6,'steel Mint data'!A:A,'steel Mint data'!L:L,"",0) -> 46500 | P6: =_xlfn.XLOOKUP(A6,'steel Mint data'!A:A,'steel Mint data'!Q:Q,"",0) -> 41000 | Q6: =_xlfn.XLOOKUP(A6,'steel Mint data'!A:A,'steel Mint data'!R:R,"",0) -> 41300
A7: =A6+1 -> 45828 | E7: =_xlfn.XLOOKUP(A7,'steel Mint data'!A:A,'steel Mint data'!D:D,"",0) -> 45000 | I7: =_xlfn.XLOOKUP(A7,'steel Mint data'!A:A,'steel Mint data'!I:I,"",0) -> 43800 | K7: =_xlfn.XLOOKUP(A7,'steel Mint data'!A:A,'steel Mint data'!L:L,"",0) -> 46400 | P7: =_xlfn.XLOOKUP(A7,'steel Mint data'!A:A,'steel Mint data'!Q:Q,"",0) -> 41000 | Q7: =_xlfn.XLOOKUP(A7,'steel Mint data'!A:A,'steel Mint data'!R:R,"",0) -> 41100
A8: =A7+1 -> 45829 | E8: =_xlfn.XLOOKUP(A8,'steel Mint data'!A:A,'steel Mint data'!D:D,"",0) -> 44800 | I8: =_xlfn.XLOOKUP(A8,'steel Mint data'!A:A,'steel Mint data'!I:I,"",0) -> 43800 | K8: =_xlfn.XLOOKUP(A8,'steel Mint data'!A:A,'steel Mint data'!L:L,"",0) -> 46300 | P8: =_xlfn.XLOOKUP(A8,'steel Mint data'!A:A,'steel Mint data'!Q:Q,"",0) -> 41000 | Q8: =_xlfn.XLOOKUP(A8,'steel Mint data'!A:A,'steel Mint data'!R:R,"",0) -> 41100
A9: =A8+1 -> 45830 | E9: =_xlfn.XLOOKUP(A9,'steel Mint data'!A:A,'steel Mint data'!D:D,"",0) -> H | I9: =_xlfn.XLOOKUP(A9,'steel Mint data'!A:A,'steel Mint data'!I:I,"",0) -> H | K9: =_xlfn.XLOOKUP(A9,'steel Mint data'!A:A,'steel Mint data'!L:L,"",0) -> H | P9: =_xlfn.XLOOKUP(A9,'steel Mint data'!A:A,'steel Mint data'!Q:Q,"",0) -> H | Q9: =_xlfn.XLOOKUP(A9,'steel Mint data'!A:A,'steel Mint data'!R:R,"",0) -> H
A10: =A9+1 -> 45831 | E10: =_xlfn.XLOOKUP(A10,'steel Mint data'!A:A,'steel Mint data'!D:D,"",0) -> 44500 | I10: =_xlfn.XLOOKUP(A10,'steel Mint data'!A:A,'steel Mint data'!I:I,"",0) -> 43600 | K10: =_xlfn.XLOOKUP(A10,'steel Mint data'!A:A,'steel Mint data'!L:L,"",0) -> 45700 | P10: =_xlfn.XLOOKUP(A10,'steel Mint data'!A:A,'steel Mint data'!Q:Q,"",0) -> 40800 | Q10: =_xlfn.XLOOKUP(A10,'steel Mint data'!A:A,'steel Mint data'!R:R,"",0) -> 41000
A11: =A10+1 -> 45832 | E11: =_xlfn.XLOOKUP(A11,'steel Mint data'!A:A,'steel Mint data'!D:D,"",0) -> 44400 | I11: =_xlfn.XLOOKUP(A11,'steel Mint data'!A:A,'steel Mint data'!I:I,"",0) -> 43300 | K11: =_xlfn.XLOOKUP(A11,'steel Mint data'!A:A,'steel Mint data'!L:L,"",0) -> 45700 | P11: =_xlfn.XLOOKUP(A11,'steel Mint data'!A:A,'steel Mint data'!Q:Q,"",0) -> 40400 | Q11: =_xlfn.XLOOKUP(A11,'steel Mint data'!A:A,'steel Mint data'!R:R,"",0) -> 41000
A12: =A11+1 -> 45833 | E12: =_xlfn.XLOOKUP(A12,'steel Mint data'!A:A,'steel Mint data'!D:D,"",0) -> 44400 | I12: =_xlfn.XLOOKUP(A12,'steel Mint data'!A:A,'steel Mint data'!I:I,"",0) -> 43500 | K12: =_xlfn.XLOOKUP(A12,'steel Mint data'!A:A,'steel Mint data'!L:L,"",0) -> 45800 | P12: =_xlfn.XLOOKUP(A12,'steel Mint data'!A:A,'steel Mint data'!Q:Q,"",0) -> 40500 | Q12: =_xlfn.XLOOKUP(A12,'steel Mint data'!A:A,'steel Mint data'!R:R,"",0) -> 41000
A13: =A12+1 -> 45834 | E13: =_xlfn.XLOOKUP(A13,'steel Mint data'!A:A,'steel Mint data'!D:D,"",0) -> 44500 | I13: =_xlfn.XLOOKUP(A13,'steel Mint data'!A:A,'steel Mint data'!I:I,"",0) -> 43600 | K13: =_xlfn.XLOOKUP(A13,'steel Mint data'!A:A,'steel Mint data'!L:L,"",0) -> 45900 | P13: =_xlfn.XLOOKUP(A13,'steel Mint data'!A:A,'steel Mint data'!Q:Q,"",0) -> 40500 | Q13: =_xlfn.XLOOKUP(A13,'steel Mint data'!A:A,'steel Mint data'!R:R,"",0) -> 41200
A14: =A13+1 -> 45835 | E14: =_xlfn.XLOOKUP(A14,'steel Mint data'!A:A,'steel Mint data'!D:D,"",0) -> 44700 | I14: =_xlfn.XLOOKUP(A14,'steel Mint data'!A:A,'steel Mint data'!I:I,"",0) -> 43400 | K14: =_xlfn.XLOOKUP(A14,'steel Mint data'!A:A,'steel Mint data'!L:L,"",0) -> 45900 | P14: =_xlfn.XLOOKUP(A14,'steel Mint data'!A:A,'steel Mint data'!Q:Q,"",0) -> 40400 | Q14: =_xlfn.XLOOKUP(A14,'steel Mint data'!A:A,'steel Mint data'!R:R,"",0) -> 41200 | S14: =49000-3450-1250-C24 -> 1185 | T14: =49000-1000-3450-F24 -> 1775
A15: =A14+1 -> 45836 | E15: =_xlfn.XLOOKUP(A15,'steel Mint data'!A:A,'steel Mint data'!D:D,"",0) -> 44600 | I15: =_xlfn.XLOOKUP(A15,'steel Mint data'!A:A,'steel Mint data'!I:I,"",0) -> 43400 | K15: =_xlfn.XLOOKUP(A15,'steel Mint data'!A:A,'steel Mint data'!L:L,"",0) -> 45800 | P15: =_xlfn.XLOOKUP(A15,'steel Mint data'!A:A,'steel Mint data'!Q:Q,"",0) -> 40200 | Q15: =_xlfn.XLOOKUP(A15,'steel Mint data'!A:A,'steel Mint data'!R:R,"",0) -> 41000
A16: =A15+1 -> 45837 | E16: =_xlfn.XLOOKUP(A16,'steel Mint data'!A:A,'steel Mint data'!D:D,"",0) -> H | I16: =_xlfn.XLOOKUP(A16,'steel Mint data'!A:A,'steel Mint data'!I:I,"",0) -> H | K16: =_xlfn.XLOOKUP(A16,'steel Mint data'!A:A,'steel Mint data'!L:L,"",0) -> H | P16: =_xlfn.XLOOKUP(A16,'steel Mint data'!A:A,'steel Mint data'!Q:Q,"",0) -> H | Q16: =_xlfn.XLOOKUP(A16,'steel Mint data'!A:A,'steel Mint data'!R:R,"",0) -> H
A17: =A16+1 -> 45838 | E17: =_xlfn.XLOOKUP(A17,'steel Mint data'!A:A,'steel Mint data'!D:D,"",0) -> 44500 | I17: =_xlfn.XLOOKUP(A17,'steel Mint data'!A:A,'steel Mint data'!I:I,"",0) -> 43300 | K17: =_xlfn.XLOOKUP(A17,'steel Mint data'!A:A,'steel Mint data'!L:L,"",0) -> 45800 | P17: =_xlfn.XLOOKUP(A17,'steel Mint data'!A:A,'steel Mint data'!Q:Q,"",0) -> 39900 | Q17: =_xlfn.XLOOKUP(A17,'steel Mint data'!A:A,'steel Mint data'!R:R,"",0) -> 41000
E18: =_xlfn.XLOOKUP(A18,'steel Mint data'!A:A,'steel Mint data'!D:D,"",0) | I18: =_xlfn.XLOOKUP(A18,'steel Mint data'!A:A,'steel Mint data'!I:I,"",0) | K18: =_xlfn.XLOOKUP(A18,'steel Mint data'!A:A,'steel Mint data'!L:L,"",0) | Q18: =_xlfn.XLOOKUP(A18,'steel Mint data'!A:A,'steel Mint data'!R:R,"",0)
E19: =SUM(E3:E18) -> 582800 | I19: =SUM(I3:I18) -> 568300 | K19: =SUM(K3:K18) -> 599600 | P19: =SUM(P3:P18) -> 529100 | Q19: =SUM(Q3:Q18) -> 535200 | S19: =49000-3450-1250-C24 -> 1185 | T19: =49000-3450-1000-F24 -> 1775
B20: Amba Shakti (NCR) | C20: API (Raipur) | D20: Aditya Industries (Mandi) | E20: Shree Ganesh (Rourkela) | F20: SKA Raipur | G20: Amba Gwalior | H20: Rajasthan | S20: =49000-3450-1250-C25 -> 685 | T20: =49000-3450-1000-F25 -> 1275
A21: Avg Price - Divided by no of days steel mint price is available | B21: =E19/O21 -> 44830.769 | C21: =P19/O21 -> 40700 | D21: =K19/O21 -> 46123.077 | E21: =Q19/O21 -> 41169.231 | F21: =C21 -> 40700 | G21: =B21-800 -> 44030.769 | H21: =I19/O21 -> 43715.385 | K21: =C24+1250+3500+2000 -> 49865 | M21: =D24+1000+1200+2500 -> 51473.077 | O21: =COUNT(P3:P18) -> 13 | R21: =53500-1350-1000-G24 -> 5719.2308 | S21: =S19-S20 -> 500 | T21: =T19-T20 -> 500
A22: BIS | B22: 1200 | C22: 2150 | D22: 400 | E22: 2200 | F22: 1800 | G22: 1200 | H22: 800 | J22: =49500-1000-1000-G24 -> 2069.2308 | R22: =53500-1350-1000-G25 -> 5350
A23: Loading Charges | B23: 200 | C23: 265 | D23: 250 | E23: 275 | F23: 275 | G23: 200 | H23: 270 | J23: =C24+1250+3000 -> 47365 | K23: =50500-G24-1000-1000 -> 3069.2308 | R23: =50000-1000-1000-G24 -> 2569.2308
A24: Actual PO Price (base dia): A | B24: =SUM(B21:B23) -> 46230.769 | C24: =SUM(C21:C23) -> 43115 | D24: =SUM(D21:D23) -> 46773.077 | E24: =SUM(E21:E23) -> 43644.231 | F24: =SUM(F21:F23) -> 42775 | G24: =SUM(G21:G23) -> 45430.769 | H24: =SUM(H21:H23) -> 44785.385 | I24: =C24+3500 -> 46615 | J24: =D24-B24 -> 542.30769 | K24: =J24-150 -> 392.30769 | M24: =50500-G24-1000-1000 -> 3069.2308 | O24: =52700-3700 -> 49000 | P24: =O24-1000-1000-G24 -> 1569.2308 | R24: =50000-1000-1000-G25 -> 2200 | S24: =R23-R24 -> 369.23077
A25: Notional PO: B | B25: 46700 | C25: 43615 | D25: 47250 | F25: 43275 | G25: 45800 | H25: 45275 | I25: =B24+500 -> 46730.769 | J25: =55500-51800 -> 3700
A26: Change (A-B) | B26: =B24-B25 -> -469.23077 | C26: =C24-C25 -> -500 | D26: =D24-D25 -> -476.92308 | E26: =E24-E25 -> 43644.231 | F26: =F24-F25 -> -500 | G26: =G24-G25 -> -369.23077 | H26: =H24-H25 -> -489.61538 | N26: =52700-4000 -> 48700 | R26: =49700-1200-B24 -> 2269.2308
L27: =50600-B24 -> 4369.2308 | Q27: =49800-600-D24 -> 2426.9231 | R27: =49700-1200-B25 -> 1800 | S27: =R26-R27 -> 469.23077
A28: Current PL | B28: 51300 | C28: 48550 | D28: 51800 | E28: 49650 | F28: 48550 | G28: 50500 | H28: 50800 | K28: =49600-2900-400-C24 -> 3185 | L28: =50600-B25 -> 3900 | O28: =52700-4000 -> 48700 | Q28: =49800-600-D25 -> 1950
A29: Current ex plant NR | B29: =B28-500-(200+300+300)-250-400 -> 49350 | C29: =C28-500-(200+300+300)-250-400 -> 46600 | D29: =D28-500-(200+300+300)-250-400 -> 49850 | E29: =E28-500-(200+300+300)-250-400 -> 47700 | F29: =F28-500-(200+300+300)-250-400 -> 46600 | G29: =G28-500-(200+300+300)-250-400 -> 48550 | H29: =H28-500-(200+300+300)-250-400 -> 48850 | J29: =50000-B24 -> 3769.2308 | K29: =49600-2900-400-C25 -> 2685 | M29: =53150-3600-C24 -> 6435 | O29: =52550-4000-C24 -> 5435
A30: Current GM: C | B30: =B29-B24 -> 3119.2308 | C30: =C29-C24 -> 3485 | D30: =D29-D24 -> 3076.9231 | E30: =E29-E24 -> 4055.7692 | F30: =F29-F24 -> 3825 | G30: =G29-G24 -> 3119.2308 | H30: =H29-H24 -> 4064.6154 | K30: =K28-K29 -> 500 | M30: =53150-3600-C25 -> 5935 | N30: =M29-M30 -> 500 | O30: =52550-4000-C25 -> 4935 | S30: =49000-3550-1250-C24 -> 1085 | T30: =49000-1000-1000-G24 -> 1569.2308 | U30: =49000-3450-1000-F24 -> 1775
Q31: =49000-1000-1000-G24 -> 1569.2308 | R31: =49700-1050-D24 -> 1876.9231 | S31: =49000-3550-1250-C25 -> 585 | T31: =49000-1000-1000-G25 -> 1200 | U31: =49000-3450-1000-F25 -> 1275
B32: =B24+1100+1800 -> 49130.769 | D32: =C24+1250+3500+2000 -> 49865 | G32: =50000-1500-G24-1000 -> 2069.2308 | K32: 5 | L32: 9 | M32: =K32-L32 -> -4 | Q32: =49000-1000-1000-G25 -> 1200 | R32: =49700-1050-D25 -> 1400
D33: =50000-3500-1250-C24 -> 2135 | F33: =D24-B24 -> 542.30769 | L33: =51200-1200-B24 -> 3769.2308
G34: =G24+1000+1000+2000 -> 49430.769 | H34: =49000+3500 -> 52500 | J34: =50600-1200-B24 -> 3169.2308 | L34: =51200-1000-D24 -> 3426.9231 | O34: =50200-200-2500 -> 47500 | P34: =47000+2500+200 -> 49700
A35: Plant | B35: Jun H1 notional | D35: =49000-700-B24 -> 2069.2308 | E35: =C24+1250+3500+2000 -> 49865 | J35: =50600-550-D24 -> 3276.9231 | R35: =C24+1250+2000 -> 46365 | S35: =51000-1440-500-800-D24 -> 1486.9231
A36: Sikandarabad | B36: 47200 | S36: =51000-1440-500-800-D25 -> 1010
A37: API, Raipur | B37: 44915 | F37: =49500-G24-1000-2000 -> 1069.2308 | G37: =49700-1050-800-D24 -> 1076.9231 | H37: =G24+1000+1000+2000 -> 49430.769 | R37: =46000 -> 46000
A38: SKA, Raipur | B38: 44575 | G38: =49700-1050-800-D25 -> 600 | K38: =49700-800-1050-D24 -> 1076.9231 | O38: =50600-2600-200-C24-1250 -> 3435 | R38: =R37-C24 -> 2885
A39: Kala Amb | B39: 47550 | H39: =48000-G24-1000 -> 1569.2308 | K39: =49700-1200-B24 -> 2269.2308 | L39: =(K39*42+K38*126)/168 -> 1375 | O39: =50600-2600-200-C25-1250 -> 2935 | P39: =O38-O39 -> 500
A40: Gwalior | B40: =B36-800 -> 46400 | D40: =53000-1800-B40-1000 -> 3800
...

Sheet Jul'25 H1 temp
B1: Fe 500
A2: Region / Date | B2: Ex-Ahmedabad | C2: Ex-Bangalore | D2: Ex-Chennai | E2: Ex-Delhi/NCR | F2: Ex-Durgapur | G2: Ex-Goa | H2: Ex-Hyderabad | I2: Ex-Jaipur | J2: Ex-Jalna | K2: Ex-Mandi Gobindgarh | L2: Ex-Mumbai | M2: Ex-Muzaffarnagar | N2: Ex-Patna | O2: Ex-Raigarh | P2: Ex-Raipur | Q2: Ex-Rourkela
A3: 45839 | B3: =_xlfn.XLOOKUP(A3,'steel Mint data'!A:A,'steel Mint data'!B:B,"",0) -> 43200 | E3: =_xlfn.XLOOKUP(A3,'steel Mint data'!A:A,'steel Mint data'!D:D,"",0) -> 44500 | I3: =_xlfn.XLOOKUP(A3,'steel Mint data'!A:A,'steel Mint data'!I:I,"",0) -> 43300 | K3: =_xlfn.XLOOKUP(A3,'steel Mint data'!A:A,'steel Mint data'!L:L,"",0) -> 45800 | P3: =_xlfn.XLOOKUP(A3,'steel Mint data'!A:A,'steel Mint data'!Q:Q,"",0) -> 39800 | Q3: =_xlfn.XLOOKUP(A3,'steel Mint data'!A:A,'steel Mint data'!R:R,"",0) -> 40900
A4: 45840
A5: 45841
A6: 45842
A7: 45843
A8: 45844
A9: 45845
A10: 45846 | B10: =_xlfn.XLOOKUP(A10,'steel Mint data'!A:A,'steel Mint data'!B:B,"",0) -> 42800 | E10: =_xlfn.XLOOKUP(A10,'steel Mint data'!A:A,'steel Mint data'!D:D,"",0) -> 43900 | I10: =_xlfn.XLOOKUP(A10,'steel Mint data'!A:A,'steel Mint data'!I:I,"",0) -> 43000 | K10: =_xlfn.XLOOKUP(A10,'steel Mint data'!A:A,'steel Mint data'!L:L,"",0) -> 45400 | P10: =_xlfn.XLOOKUP(A10,'steel Mint data'!A:A,'steel Mint data'!Q:Q,"",0) -> 39500 | Q10: =_xlfn.XLOOKUP(A10,'steel Mint data'!A:A,'steel Mint data'!R:R,"",0) -> 41000
A11: 45847 | B11: =_xlfn.XLOOKUP(A11,'steel Mint data'!A:A,'steel Mint data'!B:B,"",0) -> 43200 | E11: =_xlfn.XLOOKUP(A11,'steel Mint data'!A:A,'steel Mint data'!D:D,"",0) -> 44400 | I11: =_xlfn.XLOOKUP(A11,'steel Mint data'!A:A,'steel Mint data'!I:I,"",0) -> 43200 | K11: =_xlfn.XLOOKUP(A11,'steel Mint data'!A:A,'steel Mint data'!L:L,"",0) -> 45500 | P11: =_xlfn.XLOOKUP(A11,'steel Mint data'!A:A,'steel Mint data'!Q:Q,"",0) -> 39700 | Q11: =_xlfn.XLOOKUP(A11,'steel Mint data'!A:A,'steel Mint data'!R:R,"",0) -> 41000
A12: 45848 | B12: =_xlfn.XLOOKUP(A12,'steel Mint data'!A:A,'steel Mint data'!B:B,"",0) -> 43200 | E12: =_xlfn.XLOOKUP(A12,'steel Mint data'!A:A,'steel Mint data'!D:D,"",0) -> 44400 | I12: =_xlfn.XLOOKUP(A12,'steel Mint data'!A:A,'steel Mint data'!I:I,"",0) -> 43200 | K12: =_xlfn.XLOOKUP(A12,'steel Mint data'!A:A,'steel Mint data'!L:L,"",0) -> 45500 | P12: =_xlfn.XLOOKUP(A12,'steel Mint data'!A:A,'steel Mint data'!Q:Q,"",0) -> 39700 | Q12: =_xlfn.XLOOKUP(A12,'steel Mint data'!A:A,'steel Mint data'!R:R,"",0) -> 40800
A13: 45849 | B13: =_xlfn.XLOOKUP(A13,'steel Mint data'!A:A,'steel Mint data'!B:B,"",0) -> 43200 | E13: =_xlfn.XLOOKUP(A13,'steel Mint data'!A:A,'steel Mint data'!D:D,"",0) -> 44300 | I13: =_xlfn.XLOOKUP(A13,'steel Mint data'!A:A,'steel Mint data'!I:I,"",0) -> 43000 | K13: =_xlfn.XLOOKUP(A13,'steel Mint data'!A:A,'steel Mint data'!L:L,"",0) -> 45500 | P13: =_xlfn.XLOOKUP(A13,'steel Mint data'!A:A,'steel Mint data'!Q:Q,"",0) -> 39500 | Q13: =_xlfn.XLOOKUP(A13,'steel Mint data'!A:A,'steel Mint data'!R:R,"",0) -> 40700
A14: 45850 | B14: =_xlfn.XLOOKUP(A14,'steel Mint data'!A:A,'steel Mint data'!B:B,"",0) -> 43200 | E14: =_xlfn.XLOOKUP(A14,'steel Mint data'!A:A,'steel Mint data'!D:D,"",0) -> 44000 | I14: =_xlfn.XLOOKUP(A14,'steel Mint data'!A:A,'steel Mint data'!I:I,"",0) -> 43000 | K14: =_xlfn.XLOOKUP(A14,'steel Mint data'!A:A,'steel Mint data'!L:L,"",0) -> 45300 | P14: =_xlfn.XLOOKUP(A14,'steel Mint data'!A:A,'steel Mint data'!Q:Q,"",0) -> 39300 | Q14: =_xlfn.XLOOKUP(A14,'steel Mint data'!A:A,'steel Mint data'!R:R,"",0) -> 40600
A15: 45851 | B15: =_xlfn.XLOOKUP(A15,'steel Mint data'!A:A,'steel Mint data'!B:B,"",0) -> H | E15: =_xlfn.XLOOKUP(A15,'steel Mint data'!A:A,'steel Mint data'!D:D,"",0) -> H | I15: =_xlfn.XLOOKUP(A15,'steel Mint data'!A:A,'steel Mint data'!I:I,"",0) -> H | K15: =_xlfn.XLOOKUP(A15,'steel Mint data'!A:A,'steel Mint data'!L:L,"",0) -> H | P15: =_xlfn.XLOOKUP(A15,'steel Mint data'!A:A,'steel Mint data'!Q:Q,"",0) -> H | Q15: =_xlfn.XLOOKUP(A15,'steel Mint data'!A:A,'steel Mint data'!R:R,"",0) -> H
A16: 45852 | B16: =_xlfn.XLOOKUP(A16,'steel Mint data'!A:A,'steel Mint data'!B:B,"",0) -> 42800 | E16: =_xlfn.XLOOKUP(A16,'steel Mint data'!A:A,'steel Mint data'!D:D,"",0) -> 43900 | I16: =_xlfn.XLOOKUP(A16,'steel Mint data'!A:A,'steel Mint data'!I:I,"",0) -> 42700 | K16: =_xlfn.XLOOKUP(A16,'steel Mint data'!A:A,'steel Mint data'!L:L,"",0) -> 45200 | P16: =_xlfn.XLOOKUP(A16,'steel Mint data'!A:A,'steel Mint data'!Q:Q,"",0) -> 39200 | Q16: =_xlfn.XLOOKUP(A16,'steel Mint data'!A:A,'steel Mint data'!R:R,"",0) -> 40200
A17: 45853 | B17: =_xlfn.XLOOKUP(A17,'steel Mint data'!A:A,'steel Mint data'!B:B,"",0) -> 42600 | E17: =_xlfn.XLOOKUP(A17,'steel Mint data'!A:A,'steel Mint data'!D:D,"",0) -> 43800 | I17: =_xlfn.XLOOKUP(A17,'steel Mint data'!A:A,'steel Mint data'!I:I,"",0) -> 42400 | K17: =_xlfn.XLOOKUP(A17,'steel Mint data'!A:A,'steel Mint data'!L:L,"",0) -> 45000 | P17: =_xlfn.XLOOKUP(A17,'steel Mint data'!A:A,'steel Mint data'!Q:Q,"",0) -> 39000 | Q17: =_xlfn.XLOOKUP(A17,'steel Mint data'!A:A,'steel Mint data'!R:R,"",0) -> 40200
B18: =_xlfn.XLOOKUP(A18,'steel Mint data'!A:A,'steel Mint data'!B:B,"",0) | S18: =49000-2500-F24 -> 4962.5 | T18: =47500-2500-F24 -> 3462.5
B19: =SUM(B3:B18) -> 344200 | E19: =SUM(E3:E18) -> 353200 | I19: =SUM(I3:I18) -> 343800 | K19: =SUM(K3:K18) -> 363200 | P19: =SUM(P3:P18) -> 315700 | Q19: =SUM(Q3:Q18) -> 325400 | S19: =49000-2500-F25 -> 4225 | T19: =47500-2500-F25 -> 2725
B20: Amba Shakti (NCR) | C20: API (Raipur) | D20: Aditya Industries (Mandi) | E20: Shree Ganesh (Rourkela) | F20: SKA Raipur | G20: Amba Gwalior | H20: Rajasthan | I20: Gujarat
A21: Avg Price - Divided by no of days steel mint price is available | B21: =E19/O21 -> 44150 | C21: =P19/O21 -> 39462.5 | D21: =K19/O21 -> 45400 | E21: =Q19/O21 -> 40675 | F21: =C21 -> 39462.5 | G21: =B21-800 -> 43350 | H21: =I19/O21 -> 42975 | I21: =B19/O21 -> 43025 | O21: =COUNT(P3:P18) -> 8 | T21: =(S18*40+T18*302)/342 -> 3637.9386
A22: BIS | B22: 1200 | C22: 2150 | D22: 400 | E22: 2200 | F22: 1800 | G22: 1200 | H22: 800 | I22: 0 | J22: 1000 | K22: =G24+2200+1000+2000 -> 49950 | M22: =G24+1000+2000 -> 47750 | Q22: =48000-1000-G24 -> 2250 | T22: =(S19*40+T19*302)/342 -> 2900.4386
A23: Loading Charges | B23: 200 | C23: 265 | D23: 250 | E23: 275 | F23: 275 | G23: 200 | H23: 270 | I23: 200 | K23: =C24+1250+1500 -> 44627.5 | L23: =K23+3500 -> 48127.5 | Q23: =49450-1450-1000-G24 -> 2250
A24: Actual PO Price (base dia): A | B24: =SUM(B21:B23) -> 45550 | C24: =SUM(C21:C23) -> 41877.5 | D24: =SUM(D21:D23) -> 46050 | E24: =SUM(E21:E23) -> 43150 | F24: =SUM(F21:F23) -> 41537.5 | G24: =SUM(G21:G23) -> 44750 | H24: =SUM(H21:H23) -> 44045 | I24: =SUM(I21:I23) -> 43225 | J24: =I24+1000+2000+2500 -> 48725
A25: Notional PO: B | B25: =B36 -> 46000 | C25: =B37 -> 42615 | D25: =B39 -> 46450 | E25: =B42 -> 43675 | F25: =B38 -> 42275 | G25: =B40 -> 45200 | H25: =B41 -> 44470 | I25: 43500 | K25: =G25-C25 -> 2585 | L25: =K25-1000 -> 1585 | O25: =48500-C25-3600-1250 -> 1035
A26: Change (A-B) | B26: =B24-B25 -> -450 | C26: =C24-C25 -> -737.5 | D26: =D24-D25 -> -400 | E26: =E24-E25 -> -525 | F26: =F24-F25 -> -737.5 | G26: =G24-G25 -> -450 | H26: =H24-H25 -> -425 | I26: =I24-I25 -> -275 | K26: 48550 | S26: =45800-3100-F24 -> 1162.5 | T26: =45800 -> 45800
K27: =C25+3000 -> 45615 | N27: =46000-3350-F24 -> 1112.5 | O27: =46000-3600-F24 -> 862.5 | Q27: =48000-1250-C24 -> 4872.5 | S27: =45800-3100-F25 -> 425
A28: Current PL | B28: 49300 | C28: 46550 | D28: 49800 | E28: 47650 | F28: 46550 | G28: 48500 | H28: 48800 | I28: 48800 | K28: =K26-K27 -> 2935 | N28: =46000-3350-F25 -> 375 | O28: =46000-3600-F25 -> 125 | Q28: =48000-1000-G24 -> 2250 | R28: =Q27-Q28 -> 2622.5
A29: Current ex plant NR | B29: =B28-500-(200+300+300)-250-400 -> 47350 | C29: =C28-500-(200+300+300)-250-400 -> 44600 | D29: =D28-500-(200+300+300)-250-400 -> 47850 | E29: =E28-500-(200+300+300)-250-400 -> 45700 | F29: =F28-500-(200+300+300)-250-400 -> 44600 | G29: =G28-500-(200+300+300)-250-400 -> 46550 | H29: =H28-500-(200+300+300)-250-400 -> 46850 | I29: =I28-500-(200+300+300)-250-400 -> 46850 | K29: =K26-3000-C25 -> 2935 | M29: =47300-1100-D24 -> 150
A30: Current GM: C | B30: =B29-B24 -> 1800 | C30: =C29-C24 -> 2722.5 | D30: =D29-D24 -> 1800 | E30: =E29-E24 -> 2550 | F30: =F29-F24 -> 3062.5 | G30: =G29-G24 -> 1800 | H30: =H29-H24 -> 2805 | I30: =I29-I24 -> 3625 | Q30: =48000-1250-C24 -> 4872.5
O31: =46000-1250-C24 -> 2872.5 | P31: =O31-O32 -> 737.5 | R31: Gwalior | S31: SKA | T31: API
B32: =B28-B24 -> 3750 | C32: =C28-C24 -> 4672.5 | D32: =D28-D24 -> 3750 | E32: =E28-E24 -> 4500 | F32: =F28-F24 -> 5012.5 | G32: =G28-G24 -> 3750 | H32: =H28-H24 -> 4755 | I32: =I28-I24 -> 5575 | N32: =46000-1000-F24 -> 3462.5 | O32: =46000-1250-C25 -> 2135 | R32: =G24+1500+1000+500 -> 47750 | S32: =F24+1000+500+3000 -> 46037.5
B33: =B28-800-300 -> 48200 | R33: =G25+1500+1000+500 -> 48200
B34: Fe 500 | C34: Fe 550D | D34: =C24+3000+1200 -> 46077.5 | L34: =3600+700 -> 4300
A35: Plant | B35: Jul H1 notional | D35: =46500-C24 -> 4622.5 | E35: =D24+800+1200 -> 48050 | F35: =B24+1500 -> 47050 | H35: =F24+500+1000+3000 -> 46037.5 | L35: =C24+1250+2000+L34 -> 49427.5 | P35: =46400-3300-1000-F24 -> 562.5
A36: Sikandarabad | B36: 46000 | O36: =F24+3000+500 -> 45037.5
A37: API, Raipur | B37: 42615 | C37: =B37+1250 -> 43865 | F37: =F24+500+3000 -> 45037.5 | H37: =45000-1000-F24 -> 2462.5
A38: SKA, Raipur | B38: 42275 | C38: =B38+1000 -> 43275 | J38: =43865+3500+1200 -> 48565 | K38: =48250 -> 48250
A39: Kala Amb | B39: 46450 | C39: =B39+800 -> 47250 | P39: =47300-1300-1000-F24 -> 3462.5
A40: Gwalior | B40: 45200 | C40: =B40+1000 -> 46200 | D40: =C40-C39 -> -1050 | I40: =46200+2000+2000 -> 50200 | P40: =47300-1300-1000-F25 -> 2725
...

Sheet Jul'25 H1
B1: Fe 500
A2: Region / Date | B2: Ex-Ahmedabad | C2: Ex-Bangalore | D2: Ex-Chennai | E2: Ex-Delhi/NCR | F2: Ex-Durgapur | G2: Ex-Goa | H2: Ex-Hyderabad | I2: Ex-Jaipur | J2: Ex-Jalna | K2: Ex-Mandi Gobindgarh | L2: Ex-Mumbai | M2: Ex-Muzaffarnagar | N2: Ex-Patna | O2: Ex-Raigarh | P2: Ex-Raipur | Q2: Ex-Rourkela
A3: 45839 | B3: =_xlfn.XLOOKUP(A3,'steel Mint data'!A:A,'steel Mint data'!B:B,"",0) -> 43200 | E3: =_xlfn.XLOOKUP(A3,'steel Mint data'!A:A,'steel Mint data'!D:D,"",0) -> 44500 | I3: =_xlfn.XLOOKUP(A3,'steel Mint data'!A:A,'steel Mint data'!I:I,"",0) -> 43300 | K3: =_xlfn.XLOOKUP(A3,'steel Mint data'!A:A,'steel Mint data'!L:L,"",0) -> 45800 | P3: =_xlfn.XLOOKUP(A3,'steel Mint data'!A:A,'steel Mint data'!Q:Q,"",0) -> 39800 | Q3: =_xlfn.XLOOKUP(A3,'steel Mint data'!A:A,'steel Mint data'!R:R,"",0) -> 40900
A4: 45840 | B4: =_xlfn.XLOOKUP(A4,'steel Mint data'!A:A,'steel Mint data'!B:B,"",0) -> 43000 | E4: =_xlfn.XLOOKUP(A4,'steel Mint data'!A:A,'steel Mint data'!D:D,"",0) -> 44400 | I4: =_xlfn.XLOOKUP(A4,'steel Mint data'!A:A,'steel Mint data'!I:I,"",0) -> 43300 | K4: =_xlfn.XLOOKUP(A4,'steel Mint data'!A:A,'steel Mint data'!L:L,"",0) -> 45700 | P4: =_xlfn.XLOOKUP(A4,'steel Mint data'!A:A,'steel Mint data'!Q:Q,"",0) -> 39900 | Q4: =_xlfn.XLOOKUP(A4,'steel Mint data'!A:A,'steel Mint data'!R:R,"",0) -> 41000
A5: 45841 | B5: =_xlfn.XLOOKUP(A5,'steel Mint data'!A:A,'steel Mint data'!B:B,"",0) -> 42800 | E5: =_xlfn.XLOOKUP(A5,'steel Mint data'!A:A,'steel Mint data'!D:D,"",0) -> 44200 | I5: =_xlfn.XLOOKUP(A5,'steel Mint data'!A:A,'steel Mint data'!I:I,"",0) -> 43200 | K5: =_xlfn.XLOOKUP(A5,'steel Mint data'!A:A,'steel Mint data'!L:L,"",0) -> 45500 | P5: =_xlfn.XLOOKUP(A5,'steel Mint data'!A:A,'steel Mint data'!Q:Q,"",0) -> 39700 | Q5: =_xlfn.XLOOKUP(A5,'steel Mint data'!A:A,'steel Mint data'!R:R,"",0) -> 40800
A6: 45842 | B6: =_xlfn.XLOOKUP(A6,'steel Mint data'!A:A,'steel Mint data'!B:B,"",0) -> 42800 | E6: =_xlfn.XLOOKUP(A6,'steel Mint data'!A:A,'steel Mint data'!D:D,"",0) -> 44200 | I6: =_xlfn.XLOOKUP(A6,'steel Mint data'!A:A,'steel Mint data'!I:I,"",0) -> 43200 | K6: =_xlfn.XLOOKUP(A6,'steel Mint data'!A:A,'steel Mint data'!L:L,"",0) -> 45500 | P6: =_xlfn.XLOOKUP(A6,'steel Mint data'!A:A,'steel Mint data'!Q:Q,"",0) -> 39400 | Q6: =_xlfn.XLOOKUP(A6,'steel Mint data'!A:A,'steel Mint data'!R:R,"",0) -> 40800
